Workbook

Sheet Cover
B2: SPACEX
B3: Probabilistic Valuation Model — Q2 2026
B5: A bottoms-up, scenario-weighted view of SpaceX (post xAI merger), prior to IPO
B6: Horizons modelled: 5-year (through 2030) · 10-year (through 2035) · 20-year (through 2045)
B8: Author
B9: Dialectic
B11: Version
B12: vF · 5 June 2026
B14: Key context shaping this model
B15: • SpaceX–xAI merger closed 2 Feb 2026 at $1.25T combined valuation ($1T SpaceX + $250B xAI)
B16: • SpaceX IPO expected late June 2026 (S-1 filed May 2026)
B17: • Starshield Space Data Network contract awarded 26 May 2026 ($2.29B, Golden Dome backbone)
... B32: and should be treated as long-dated optionality, not base-case revenue. Not investment advice.

Sheet README
B2: Methodology & Conventions
B3: Read this once. The rest of the model assumes you have.
B5: Color conventions
B6: Blue text | C6: Hardcoded inputs you can edit to change the model
B7: Yellow background | C7: KEY inputs that have outsized effect on valuation — change with care
B8: Black text | C8: Formulas — do not overwrite unless you intend to break the model
B9: Green text | C9: Cross-sheet links pulling from another tab
B10: Gold fill | C10: Totals and headline outputs
B12: Scenario logic
B13: Three scenarios | C13: Bear / Base / Bull. Each with its own revenue path, EBITDA margin, and CapEx %.
B14: Scenario weights | C14: Per-line Bear/Base/Bull weights on Scenario_Engine; must sum to 100%.
B15: Probability of materialization | C15: Separate 0-100% input for each speculative line. Multiplies through.
B16: Expected free cash flow | C16: EV = scenario-weighted UFCF × materialization probability. This feeds DCF.
B18: Revenue construction
B19: Three-phase CAGR | C19: Each business line is modelled with three growth phases: ramp (2026-2030), mid (2031-2035), mature (2036-2045).
B20: Editable per scenario | C20: All three CAGRs are settable per scenario on each business-line tab.
B21: Starting revenue | C21: 2026 starting revenue is a hardcoded input per scenario.
B22: Waypoints visible | C22: Yellow-highlighted 2030/2035/2045 cells are the headline horizon outputs per scenario.
B24: Valuation method
B25: Discounted cash flow | C25: Unlevered FCF discounted at WACC. Terminal value via Gordon Growth.
B26: Enterprise → equity | C26: EV less net debt = equity value. Per-share at fully-diluted share count.
B27: Three horizons | C27: 5yr (terminal at end 2030), 10yr (end 2035), 20yr (end 2045) — all on Summary.
B28: Probability-weighted EV | C28: Final EV = Σ business lines × scenario × materialization.
B30: What this model is NOT
B31: Not predictive | C31: Outputs are conditional on assumptions you can challenge. Treat as a thinking tool.
B32: Not multiple-driven | C32: Public comps are weak for SpaceX. DCF is used because no good multiple exists.
B33: Not policy-aware | C33: Mars/Moon land sales face the 1967 Outer Space Treaty — kept at low probability.
B34: Not synergy-priced | C34: xAI cost/revenue synergies with SpaceX are modelled conservatively.

Sheet Thesis
B2: INVESTMENT THESIS
B3: SpaceX — Q2 2026 · what we are underwriting, what has to be true, what breaks it
B7: ONE-LINE THESIS
B8: SpaceX is actually 12 different current and near-term businesses backstopped by a pure monopoly on launch and LEO connectivity that is reinvesting its cash flows into — AI compute (Colossus), Orbital Data Centres (ODCs) and the Starship platform for interplanetary dominance. We believe that the business will return to cash-flow positive operating position in the short term and represents an incredibly compelling option on the inspiring future the constellation of space industries that are enabled by SpaceX's unique position. We also note the recently-closed merger with xAI (Feb 2026, $1.25T combined entity), which is highly strategic and synergistic and adds further short-term growth to this story.
B10: WHAT WE ARE UNDERWRITING | C10: WHAT HAS TO BE TRUE | D10: WHAT BREAKS THE THESIS
B11: Pillar 1 · STARLINK as the cash-flow engine | C11: Pillar 1 · STARLINK — conditions | D11: Pillar 1 · STARLINK — break points
B12: 10.3M subs, 9,600+ sats, 164 countries (S-1). Connectivity segment ran ~$13Bn run-rate Q1 2026 at Adj EBITDA mgn 64%. This is a $130-200Bn revenue business by 2030 with SaaS-like economics once satellite fleet is depreciated. Funds the rest of SpaceX. | C12: • ARPU floors at $40-50/month even as international mix grows. • Subs reach 50M+ by 2030 (5x current). • D2C (satellite-to-cell) adds incremental ARPU not cannibalises terrestrial. • Aviation/Maritime ($3Bn 2026 seed) converts to multi-billion stable enterprise revenue. • Margins hold above 60% as new gens of sats launch on Starship at lower unit cost. | D12: • Kuiper/AST/Chinese constellations force ARPU compression 30%+ within 5 years. • Spectrum disputes (FCC, ITU) limit constellation expansion. • D2C remains a one-carrier (T-Mobile) niche product. • Insurance/regulatory costs for LEO debris cleanup spike unit economics. • Geopolitical: countries ban Starlink in major markets (Brazil precedent).
B13: Pillar 2 · STARSHIP as the cost-down enabler | C13: Pillar 2 · STARSHIP — conditions | D13: Pillar 2 · STARSHIP — break points
B14: $3Bn R&D in 2025 alone (S-1). Starship unlocks Starlink v3 (more bandwidth/sat), HLS delivery (NASA), point-to-point earth travel, and Mars optionality. Without Starship, the 2030+ Starlink and lunar/Mars stories don't compound. | C14: • Orbital flight to commercial cadence by 2028 (currently end-2026 milestone slip risk). • Per-kg cost drops to <$200 (vs Falcon 9 ~$1,500). • Rapid reusability — hundreds of flights per booster. • NASA HLS milestones met on Artemis III/IV. | D14: • 24-month+ Starship slip. Cuts Starlink v3 economics. Forces Falcon 9 dependence. • Reusability breakthrough fails to materialise (each booster <10 flights). • HLS contract loss / cancellation under new administration. • Major Starship test failure with loss of life or environmental damage.
B15: Pillar 3 · AI / Colossus / xAI optionality | C15: Pillar 3 · AI — conditions | D15: Pillar 3 · AI — break points
B16: xAI (merged Feb 2026) and Colossus DC build-out. SpaceX captures Musk's compute infrastructure. Use of IPO proceeds explicitly includes 'AI compute infrastructure' per S-1. | C16: • Colossus captures ~25% of US frontier-model training spend by 2028. • xAI/Grok generates $10Bn+ revenue by 2028 (vs sub-$3Bn 2025). • Capex scale (1M GPU/yr per model assumption) is financeable without major dilution. • No regulatory action against vertically-integrated AI provider with major govt contracts. | D16: • AI capex cycle deflates (Nvidia/cloud overbuild thesis). • Open-source models or efficiency breakthroughs cut training compute demand 50%+. • Hyperscaler verticalisation (OpenAI/Anthropic in-house chips) squeezes 3rd-party compute providers. • Musk attention dilution event: xAI roadmap stalls.
B17: Pillar 4 · GOVT / STARSHIELD revenue moat | C17: Pillar 4 · GOVT — conditions | D17: Pillar 4 · GOVT — break points
B18: Starshield ($2.29Bn contract anchored May 2026), NASA HLS, USSF/NRO launches. Government revenue is contracted, recurring, and politically sticky once embedded in defence architecture. | C18: • Starshield contracts renew and expand at 18-32% margins. • USSF / NRO continues sole-source / preferred-vendor status. • ITAR/export controls don't tighten on dual-use Starlink/Starshield architecture. • Musk's relationship with sitting administration remains workable. | D18: • Blue Sweep in Nov-26 or Dem President could hold business back. Political event: Musk-administration breakdown leads to contract pulls (~30% of segment). • CFIUS review of foreign customer access. • Congressional antagonism wrt procurement practices. • Multi-vendor mandate forces competition (Northrop, RTX, Blue Origin take share).
B20: MODEL LEVERS — each thesis pillar maps to specific assumptions in the workbook
B21: Pillar | C21: Key model cell(s) | D21: What to watch
B22: Starlink cash flow | C22: Starlink_Consumer (Base 2026 rev $8B, ARPU $66, blended margin 50%) | D22: If consensus ARPU falls below $50 or subs growth stalls below 30% YoY, sense-check immediately.
B23: Starship economics | C23: Launch_Services + xAI funding capex schedule | D23: Orbital flight cadence test. Q4 2026 / Q1 2027 milestone risk.
B24: AI / Colossus + ODCs | C24: Colossus_DCs 2026 rev $16B + 1M GPU/yr mature assumption; xAI_Software | D24: Compare Colossus revenue to S-1 Connectivity Q1'26 ($3.3B). If 2026 actual < $10B, model assumption is too aggressive.
B25: Govt / Starshield | C25: Starshield (anchored to $2.29Bn May 2026 contract), NASA_Lunar HLS | D25: Renewal cadence; multi-vendor language in next NDAA / USSF procurement notices.
B26: Speculative tail | C26: PlanetX_Land, Asteroid_Mining, Mars_Moon, Lunar_Mfg, Orbital_DCs | D26: Treat as zero in base case. Only credit Bull scenarios. Re-run Comps with $251Bn removed for comparison.

Sheet Summary
C2: Summary — Headline Outputs
C3: Probability-weighted enterprise value, equity value, and per-share value across horizons
C5: Probability-weighted valuation by horizon
C6: Horizon | D6: Ent. Value ($M) | E6: Eq. Val ($M) | F6: Per Share ($) | G6: Implied EV ($B)
C7: 5-year | D7: =DCF!F13 -> 840458.19 | E7: =DCF!E19 -> 827199.19 | F7: =DCF!F19 -> 61.731282 | G7: =D7/1000 -> 840.45819
C8: 10-year | D8: =DCF!F14 -> 2685974 | E8: =DCF!E20 -> 2672715 | F8: =DCF!F20 -> 199.45634 | G8: =D8/1000 -> 2685.974
C9: 20-year | D9: =DCF!F15 -> 10191466 | E9: =DCF!E21 -> 10178207 | F9: =DCF!F21 -> 759.56771 | G9: =D9/1000 -> 10191.466
C10: Blended Fair Value | D10: =D7*$D$35+D8*$D$36+D9*$D$37 -> 2421489.5 | E10: =E7*$D$35+E8*$D$36+E9*$D$37 -> 2408230.5 | F10: =F7*$D$35+F8*$D$36+F9*$D$37 -> 179.7187 | G10: =G7*$D$35+G8*$D$36+G9*$D$37 -> 2421.4895
C12: Major Reference points
C13: Feb 2026 SpaceX–xAI merger valuation | D13: $1,250B | E13: Combined SpaceX ($1T) + xAI ($250B)
C14: 2026 implied IPO valuation range | D14: $1.5–2.0T | E14: Banker leaks; based on consensus $100+ IPO price × ~1.85B shares
C15: 2025 SpaceX revenue (actual) | D15: $18.7B | E15: +33% YoY; from S-1 filing
C16: 2025 SpaceX Adj EBITDA (actual) | D16: $6.6B | E16: From S-1 filing
C18: Probability-weighted revenue at horizon endpoints ($M)
C19: Business Line | D19: 2030 Revenue | E19: 2035 Revenue | F19: 2045 Revenue | G19: Notes
B20: 1 | C20: Launch Services & Lunar Vehicles | D20: ='P&L_Consolidated'!G7 -> 52361.288 | E20: ='P&L_Consolidated'!L7 -> 207734.38 | F20: ='P&L_Consolidated'!V7 -> 1753174.7 | G20: Falcon + Starship + HLS Artemis lunar lander
B21: 2 | C21: Crewed Spaceflight | D21: ='P&L_Consolidated'!G8 -> 6045.9067 | E21: ='P&L_Consolidated'!L8 -> 15716.949 | F21: ='P&L_Consolidated'!V8 -> 58265.392 | G21: NASA CCP/CRS + Polaris/Axiom + Starports/P2P (tourism/private merged)
B22: 3 | C22: Other Space Services | D22: ='P&L_Consolidated'!G9 -> 573.51036 | E22: ='P&L_Consolidated'!L9 -> 2180.3754 | F22: ='P&L_Consolidated'!V9 -> 15525.749 | G22: Satellite servicing + orbital tug + rocketry IP licensing or manufacture/sales
B23: 4 | C23: Starlink Connectivity (Consumer + Av/Mar) | D23: ='P&L_Consolidated'!G10 -> 63825.515 | E23: ='P&L_Consolidated'!L10 -> 249694.26 | F23: ='P&L_Consolidated'!V10 -> 989981.58 | G23: Residential + business + aviation + maritime broadband (merged connectivity)
B24: 5 | C24: Starlink Direct-to-Cell | D24: ='P&L_Consolidated'!G11 -> 9991.5116 | E24: ='P&L_Consolidated'!L11 -> 94139.592 | F24: ='P&L_Consolidated'!V11 -> 990791.62 | G24: Carrier deal scaling + spectrum policy
B25: 6 | C25: Starshield & Golden Dome (Defense) | D25: ='P&L_Consolidated'!G12 -> 15401.722 | E25: ='P&L_Consolidated'!L12 -> 59352.602 | F25: ='P&L_Consolidated'!V12 -> 325904.38 | G25: Defense contract pipeline (Golden Dome, NRO)
B26: 7 | C26: xAI Software (Grok + API) | D26: ='P&L_Consolidated'!G13 -> 12200.307 | E26: ='P&L_Consolidated'!L13 -> 65348.604 | F26: ='P&L_Consolidated'!V13 -> 326970.1 | G26: Grok subs, enterprise API revenue
B27: 8 | C27: Colossus Terrestrial Data Centres | D27: ='P&L_Consolidated'!G14 -> 68191.519 | E27: ='P&L_Consolidated'!L14 -> 219904.96 | F27: ='P&L_Consolidated'!V14 -> 797628.52 | G27: 1M GPU/yr × $30B per million mature pricing
B28: 9 | C28: Orbital Data Centres | D28: ='P&L_Consolidated'!G15 -> 0 | E28: ='P&L_Consolidated'!L15 -> 68340.86 | F28: ='P&L_Consolidated'!V15 -> 1960783.4 | G28: First commercial 2031 (base); long-dated
B29: 10 | C29: Deep Space Optionality | D29: ='P&L_Consolidated'!G16 -> 0 | E29: ='P&L_Consolidated'!L16 -> 45.939975 | F29: ='P&L_Consolidated'!V16 -> 110622.97 | G29: Lunar Mfg + Asteroid + Mars/Moon (long-dated optionality merged)
B30: 11 | C30: X Platform | D30: ='P&L_Consolidated'!G17 -> 15774.079 | E30: ='P&L_Consolidated'!L17 -> 45235.993 | F30: ='P&L_Consolidated'!V17 -> 227301.68 | G30: X.com social/ads/premium + Xmoney payments (merged)
B31: 12 | C31: Terafab — Semiconductor Manufacturing | D31: ='P&L_Consolidated'!G18 -> 0 | E31: ='P&L_Consolidated'!L18 -> 36020.876 | F31: ='P&L_Consolidated'!V18 -> 1085705.8 | G31: $55B chip fab; AI5/AI6 + D3; captive + 3P sales
C32: Total | D32: =SUM(D20:D31) -> 244365.36 | E32: =SUM(E20:E31) -> 1063715.4 | F32: =SUM(F20:F31) -> 8642655.9
C34: Horizon blending weights
C35: 5-year weight | D35: =Assumptions!C35 -> 0.55
C36: 10-year weight | D36: =Assumptions!C36 -> 0.35
C37: 20-year weight | D37: =Assumptions!C37 -> 0.1
C38: Sum (should = 100%) | D38: =SUM(D35:D37) -> 1

Sheet Sum of Parts
B2: Sum-of-the-Parts: SpaceX by Business Unit
B3: Per-segment PV of 10-year UFCF (2026–2035) + Gordon terminal value. WACC and g linked to Assumptions. Tiered by confidence — anchor businesses left, speculative right.
B5: WACC | C5: =Assumptions!C15 -> 0.0900375 | D5: Terminal g | E5: =Assumptions!C16 -> 0.04 | F5: Horizon | G5: 10yr (central)
B7: Tier | C7: Business Unit | D7: PV of UFCF (10yr, $M) | E7: PV of TV ($M) | F7: Segment EV (Base, $M) | G7: Bear EV ($M) | H7: Bull EV ($M) | I7: % of total Base | J7: S-1 anchored? | P7: Chart data (sorted: anchor → plausible → speculative) | U7: Cumulative build (sorted by Base EV descending) — rebuilt
P8: Segment | Q8: Bear EV | R8: Base EV | S8: Bull EV | U8: Segment | V8: Base EV ($Bn) | W8: Cumulative Base ($Bn) | X8: Bear EV ($Bn) | Y8: Cumulative Bear ($Bn) | Z8: Bull EV ($Bn) | AA8: Cumulative Bull ($Bn)
A9: 1 | B9: ANCHOR | C9: Launch Services & Lunar Vehicles | D9: =SUMPRODUCT(Launch_Services!C43:L43,$C$26:$L$26) -> 54862.628 | E9: =(Launch_Services!L43*(1+$E$5)/($C$5-$E$5))*$L$26 -> 269033.82 | F9: =D9+E9 -> 323896.45 | G9: =F9*IFERROR(Launch_Services!L30/MAX(0.001,Launch_Services!L31),0.7)*0.7 -> 76260.265 | H9: =F9*MIN(2,MAX(1,IFERROR(Launch_Services!L32/MAX(0.001,Launch_Services!L31),1.4)))*1.1 -> 712572.19 | I9: =F9/$F$21 -> 0.14351954 | J9: Yes | P9: Starlink Connectivity | Q9: =G10/1000 -> 83.699618 | R9: =F10/1000 -> 744.569 | S9: =H10/1000 -> 1638.0518 | U9: Starlink Connectivity | V9: =F10/1000 -> 744.569 | W9: =V9 -> 744.569 | X9: =G10/1000 -> 83.699618 | Y9: =X9 -> 83.699618 | Z9: =H10/1000 -> 1638.0518 | AA9: =Z9 -> 1638.0518
A10: 2 | B10: ANCHOR | C10: Starlink Connectivity | D10: =SUMPRODUCT(Starlink!C43:L43,$C$26:$L$26) -> 130980.71 | E10: =(Starlink!L43*(1+$E$5)/($C$5-$E$5))*$L$26 -> 613588.29 | F10: =D10+E10 -> 744569 | G10: =F10*IFERROR(Starlink!L30/MAX(0.001,Starlink!L31),0.7)*0.7 -> 83699.618 | H10: =F10*MIN(2,MAX(1,IFERROR(Starlink!L32/MAX(0.001,Starlink!L31),1.4)))*1.1 -> 1638051.8 | I10: =F10/$F$21 -> 0.32992087 | J10: Yes | P10: Starlink D2C | Q10: =G15/1000 -> 28.292797 | R10: =F15/1000 -> 379.86154 | S10: =H15/1000 -> 835.69539 | U10: Starlink D2C | V10: =F15/1000 -> 379.86154 | W10: =W9+V10 -> 1124.4305 | X10: =G15/1000 -> 28.292797 | Y10: =Y9+X10 -> 111.99241 | Z10: =H15/1000 -> 835.69539 | AA10: =AA9+Z10 -> 2473.7472
A11: 3 | B11: ANCHOR | C11: Starshield | D11: =SUMPRODUCT(Starshield!C43:L43,$C$26:$L$26) -> 34177.949 | E11: =(Starshield!L43*(1+$E$5)/($C$5-$E$5))*$L$26 -> 155878.84 | F11: =D11+E11 -> 190056.79 | G11: =F11*IFERROR(Starshield!L30/MAX(0.001,Starshield!L31),0.7)*0.7 -> 42070.067 | H11: =F11*MIN(2,MAX(1,IFERROR(Starshield!L32/MAX(0.001,Starshield!L31),1.4)))*1.1 -> 418124.94 | I11: =F11/$F$21 -> 0.084214763 | J11: Yes | P11: Launch Services | Q11: =G9/1000 -> 76.260265 | R11: =F9/1000 -> 323.89645 | S11: =H9/1000 -> 712.57219 | U11: Launch Services | V11: =F9/1000 -> 323.89645 | W11: =W10+V11 -> 1448.327 | X11: =G9/1000 -> 76.260265 | Y11: =Y10+X11 -> 188.25268 | Z11: =H9/1000 -> 712.57219 | AA11: =AA10+Z11 -> 3186.3194
A12: 4 | B12: ANCHOR | C12: xAI Software | D12: =SUMPRODUCT(xAI_Software!C43:L43,$C$26:$L$26) -> 13442.087 | E12: =(xAI_Software!L43*(1+$E$5)/($C$5-$E$5))*$L$26 -> 72503.162 | F12: =D12+E12 -> 85945.249 | G12: =F12*IFERROR(xAI_Software!L30/MAX(0.001,xAI_Software!L31),0.7)*0.7 -> 13413.769 | H12: =F12*MIN(2,MAX(1,IFERROR(xAI_Software!L32/MAX(0.001,xAI_Software!L31),1.4)))*1.1 -> 189079.55 | I12: =F12/$F$21 -> 0.038082611 | J12: Yes | P12: Colossus DCs | Q12: =G13/1000 -> 58.817416 | R12: =F13/1000 -> 328.72532 | S12: =H13/1000 -> 723.1957 | U12: Colossus DCs | V12: =F13/1000 -> 328.72532 | W12: =W11+V12 -> 1777.0523 | X12: =G13/1000 -> 58.817416 | Y12: =Y11+X12 -> 247.0701 | Z12: =H13/1000 -> 723.1957 | AA12: =AA11+Z12 -> 3909.5151
A13: 5 | B13: ANCHOR | C13: Colossus DCs | D13: =SUMPRODUCT(Colossus_DCs!C43:L43,$C$26:$L$26) -> 60527.583 | E13: =(Colossus_DCs!L43*(1+$E$5)/($C$5-$E$5))*$L$26 -> 268197.74 | F13: =D13+E13 -> 328725.32 | G13: =F13*IFERROR(Colossus_DCs!L30/MAX(0.001,Colossus_DCs!L31),0.7)*0.7 -> 58817.416 | H13: =F13*MIN(2,MAX(1,IFERROR(Colossus_DCs!L32/MAX(0.001,Colossus_DCs!L31),1.4)))*1.1 -> 723195.7 | I13: =F13/$F$21 -> 0.14565923 | J13: Yes | P13: Starshield | Q13: =G11/1000 -> 42.070067 | R13: =F11/1000 -> 190.05679 | S13: =H11/1000 -> 418.12494 | U13: Starshield | V13: =F11/1000 -> 190.05679 | W13: =W12+V13 -> 1967.1091 | X13: =G11/1000 -> 42.070067 | Y13: =Y12+X13 -> 289.14016 | Z13: =H11/1000 -> 418.12494 | AA13: =AA12+Z13 -> 4327.64
A14: 6 | B14: ANCHOR | C14: Crewed Spaceflight | D14: =SUMPRODUCT('Crewed Trips'!C43:L43,$C$26:$L$26) -> 14714.373 | E14: =('Crewed Trips'!L43*(1+$E$5)/($C$5-$E$5))*$L$26 -> 48774.974 | F14: =D14+E14 -> 63489.348 | G14: =F14*IFERROR('Crewed Trips'!L30/MAX(0.001,'Crewed Trips'!L31),0.7)*0.7 -> 6968.9925 | H14: =F14*MIN(2,MAX(1,IFERROR('Crewed Trips'!L32/MAX(0.001,'Crewed Trips'!L31),1.4)))*1.1 -> 139676.56 | I14: =F14/$F$21 -> 0.02813233 | J14: Yes | P14: xAI Software | Q14: =G12/1000 -> 13.413769 | R14: =F12/1000 -> 85.945249 | S14: =H12/1000 -> 189.07955 | U14: xAI Software | V14: =F12/1000 -> 85.945249 | W14: =W13+V14 -> 2053.0544 | X14: =G12/1000 -> 13.413769 | Y14: =Y13+X14 -> 302.55393 | Z14: =H12/1000 -> 189.07955 | AA14: =AA13+Z14 -> 4516.7196
A15: 7 | B15: PLAUSIBLE | C15: Starlink D2C | D15: =SUMPRODUCT(Starlink_D2C!C43:L43,$C$26:$L$26) -> 47415.05 | E15: =(Starlink_D2C!L43*(1+$E$5)/($C$5-$E$5))*$L$26 -> 332446.49 | F15: =D15+E15 -> 379861.54 | G15: =F15*IFERROR(Starlink_D2C!L30/MAX(0.001,Starlink_D2C!L31),0.7)*0.7 -> 28292.797 | H15: =F15*MIN(2,MAX(1,IFERROR(Starlink_D2C!L32/MAX(0.001,Starlink_D2C!L31),1.4)))*1.1 -> 835695.39 | I15: =F15/$F$21 -> 0.16831785 | J15: Yes (T-Mobile) | P15: Crewed Spaceflight | Q15: =G14/1000 -> 6.9689925 | R15: =F14/1000 -> 63.489348 | S15: =H14/1000 -> 139.67656 | U15: Crewed Spaceflight | V15: =F14/1000 -> 63.489348 | W15: =W14+V15 -> 2116.5437 | X15: =G14/1000 -> 6.9689925 | Y15: =Y14+X15 -> 309.52292 | Z15: =H14/1000 -> 139.67656 | AA15: =AA14+Z15 -> 4656.3961
A16: 8 | B16: PLAUSIBLE | C16: Other Space Services | D16: =SUMPRODUCT(Other_Services!C43:L43,$C$26:$L$26) -> 1118.0775 | E16: =(Other_Services!L43*(1+$E$5)/($C$5-$E$5))*$L$26 -> 4989.8954 | F16: =D16+E16 -> 6107.9729 | G16: =F16*IFERROR(Other_Services!L30/MAX(0.001,Other_Services!L31),0.7)*0.7 -> 497.29509 | H16: =F16*MIN(2,MAX(1,IFERROR(Other_Services!L32/MAX(0.001,Other_Services!L31),1.4)))*1.1 -> 13437.54 | I16: =F16/$F$21 -> 0.0027064621 | J16: Satellite service + orbital tug + Rocketry IP license | P16: Terafab | Q16: =G18/1000 -> 6.2297376 | R16: =F18/1000 -> 53.956821 | S16: =H18/1000 -> 118.70501 | U16: Terafab | V16: =F18/1000 -> 53.956821 | W16: =W15+V16 -> 2170.5005 | X16: =G18/1000 -> 6.2297376 | Y16: =Y15+X16 -> 315.75266 | Z16: =H18/1000 -> 118.70501 | AA16: =AA15+Z16 -> 4775.1012
A17: 9 | B17: PLAUSIBLE | C17: X Platform | D17: =SUMPRODUCT('X Platform'!C43:L43,$C$26:$L$26) -> 10371.258 | E17: =('X Platform'!L43*(1+$E$5)/($C$5-$E$5))*$L$26 -> 43103.677 | F17: =D17+E17 -> 53474.934 | G17: =F17*IFERROR('X Platform'!L30/MAX(0.001,'X Platform'!L31),0.7)*0.7 -> 7846.3845 | H17: =F17*MIN(2,MAX(1,IFERROR('X Platform'!L32/MAX(0.001,'X Platform'!L31),1.4)))*1.1 -> 117644.86 | I17: =F17/$F$21 -> 0.023694912 | J17: Yes (Conn. seg.) | P17: X Platform | Q17: =G17/1000 -> 7.8463845 | R17: =F17/1000 -> 53.474934 | S17: =H17/1000 -> 117.64486 | U17: X Platform | V17: =F17/1000 -> 53.474934 | W17: =W16+V17 -> 2223.9755 | X17: =G17/1000 -> 7.8463845 | Y17: =Y16+X17 -> 323.59905 | Z17: =H17/1000 -> 117.64486 | AA17: =AA16+Z17 -> 4892.746
A18: 10 | B18: PLAUSIBLE | C18: Terafab — Semiconductor Manufacturing | D18: =SUMPRODUCT(Terafab!C43:L43,$C$26:$L$26) -> 5193.8734 | E18: =(Terafab!L43*(1+$E$5)/($C$5-$E$5))*$L$26 -> 48762.948 | F18: =D18+E18 -> 53956.821 | G18: =F18*IFERROR(Terafab!L30/MAX(0.001,Terafab!L31),0.7)*0.7 -> 6229.7376 | H18: =F18*MIN(2,MAX(1,IFERROR(Terafab!L32/MAX(0.001,Terafab!L31),1.4)))*1.1 -> 118705.01 | I18: =F18/$F$21 -> 0.023908438 | J18: Adjacent (Tesla) | P18: Orbital DCs | Q18: =G19/1000 -> 2.3282476 | R18: =F19/1000 -> 26.711956 | S18: =H19/1000 -> 77.017301 | U18: Orbital DCs | V18: =F19/1000 -> 26.711956 | W18: =W17+V18 -> 2250.6874 | X18: =G19/1000 -> 2.3282476 | Y18: =Y17+X18 -> 325.92729 | Z18: =H19/1000 -> 77.017301 | AA18: =AA17+Z18 -> 4969.7633
A19: 11 | B19: SPECULATIVE | C19: Orbital DCs | D19: =SUMPRODUCT(Orbital_DCs!C43:L43,$C$26:$L$26) -> 2016.1022 | E19: =(Orbital_DCs!L43*(1+$E$5)/($C$5-$E$5))*$L$26 -> 24695.854 | F19: =D19+E19 -> 26711.956 | G19: =F19*IFERROR(Orbital_DCs!L30/MAX(0.001,Orbital_DCs!L31),0.5)*0.4 -> 2328.2476 | H19: =F19*MIN(3,MAX(1,IFERROR(Orbital_DCs!L32/MAX(0.001,Orbital_DCs!L31),2)))*1.2 -> 77017.301 | I19: =F19/$F$21 -> 0.011836152 | J19: No | P19: Other Space Services | Q19: =G16/1000 -> 0.49729509 | R19: =F16/1000 -> 6.1079729 | S19: =H16/1000 -> 13.43754 | U19: Other Space Services | V19: =F16/1000 -> 6.1079729 | W19: =W18+V19 -> 2256.7954 | X19: =G16/1000 -> 0.49729509 | Y19: =Y18+X19 -> 326.42459 | Z19: =H16/1000 -> 13.43754 | AA19: =AA18+Z19 -> 4983.2008
A20: 12 | B20: SPECULATIVE | C20: Deep Space Optionality | D20: =SUMPRODUCT('Deep Space Option'!C43:L43,$C$26:$L$26) -> 2.2759525 | E20: =('Deep Space Option'!L43*(1+$E$5)/($C$5-$E$5))*$L$26 -> 13.181843 | F20: =D20+E20 -> 15.457795 | G20: =F20*IFERROR('Deep Space Option'!L30/MAX(0.001,'Deep Space Option'!L31),0.5)*0.4 -> 1.7110895 | H20: =F20*MIN(3,MAX(1,IFERROR('Deep Space Option'!L32/MAX(0.001,'Deep Space Option'!L31),2)))*1.2 -> 55.648062 | I20: =F20/$F$21 -> 6.8493977e-06 | J20: Lunar Mfg + Asteroid + Mars/Moon (LT optionality) | P20: Deep Space Optionality | Q20: =G20/1000 -> 0.0017110895 | R20: =F20/1000 -> 0.015457795 | S20: =H20/1000 -> 0.055648062 | U20: Deep Space Optionality | V20: =F20/1000 -> 0.015457795 | W20: =W19+V20 -> 2256.8108 | X20: =G20/1000 -> 0.0017110895 | Y20: =Y19+X20 -> 326.4263 | Z20: =H20/1000 -> 0.055648062 | AA20: =AA19+Z20 -> 4983.2565
B21: TOTAL SOTP | C21: Enterprise Value (SOTP, 10yr) | D21: =SUM(D9:D20) -> 374821.97 | E21: =SUM(E9:E20) -> 1881988.9 | F21: =SUM(F9:F20) -> 2256810.8 | G21: =SUM(G9:G20) -> 326426.3 | H21: =SUM(H9:H20) -> 4983256.5 | I21: =SUM(I9:I20) -> 1
F23: Amount ($M)
B24: Discount factor (10yr) | L24: Year offsets used in PV calcs (1–10). Hidden helper.
B25: Year # | C25: 1 | D25: 2 | E25: 3 | F25: 4 | G25: 5 | H25: 6 | I25: 7 | J25: 8 | K25: 9 | L25: 10
B26: Disc factor | C26: =1/(1+$C$5)^C25 -> 0.91739963 | D26: =1/(1+$C$5)^D25 -> 0.84162208 | E26: =1/(1+$C$5)^E25 -> 0.77210379 | F26: =1/(1+$C$5)^F25 -> 0.70832773 | G26: =1/(1+$C$5)^G25 -> 0.6498196 | H26: =1/(1+$C$5)^H25 -> 0.59614426 | I26: =1/(1+$C$5)^I25 -> 0.54690252 | J26: =1/(1+$C$5)^J25 -> 0.50172817 | ... L26: =1/(1+$C$5)^L25 -> 0.42226551
B28: RECONCILIATION: SoTP → DCF (10-yr horizon, $M)
B29: Bridge component | C29: Source / formula | F29: Amount ($M)
B30: SoTP base (raw UFCF + TV) | C30: Sum of segment PV(UFCF) + PV(TV) on segment row 43 | F30: =F21 -> 2256810.8
B31: (+) D&A tax shield | C31: PV of (D&A × tax) + PV of TV on year-10 D&A — corporate-level in DCF | F31: =SUMPRODUCT(DCF!C43:L43,DCF!C8:L8)+(DCF!L43*(1+Assumptions!$C$16)/(Assumptions!$C$15-Assumptions!$C$16))*DCF!L8 -> 286216.31
B32: (+) NOL utilisation benefit | C32: PV of (NOL used × tax) — one-shot 2026–27, then exhausted | F32: =SUMPRODUCT(DCF!C49:L49,DCF!C8:L8) -> 4726.9676
B33: (−) ΔNWC drag | C33: PV of ΔNWC — working capital investment as revenue scales | F33: =SUMPRODUCT(DCF!C45:L45,DCF!C8:L8)+(DCF!L45*(1+Assumptions!$C$16)/(Assumptions!$C$15-Assumptions!$C$16))*DCF!L8 -> -91464.872
B34: (+) Segment → Consolidated UFCF (PV of flows) | C34: PV of consolidated UFCF (P&L row 52) minus sum of segment PV(UFCF). Captures overhead/eliminations not in segment tabs. | F34: =SUMPRODUCT(DCF!C9:L9)-'Sum of Parts'!D21 -> 50314.183
B35: (+) Segment → Consolidated UFCF (terminal value) | C35: TV using consolidated year-10 UFCF (DCF!L7) minus SoTP TV using sum of segment year-10 UFCF. Same overhead/elimination effect, capitalised into perpetuity. | F35: =(DCF!L7*(1+Assumptions!$C$16)/(Assumptions!$C$15-Assumptions!$C$16))*DCF!L8-'Sum of Parts'!E21 -> 179370.58
B36: DCF EV (Adjusted UFCF, 10yr) | C36: Should approximate DCF!F14 | F36: =F30+F31+F32+F33+F34+F35 -> 2685974
B37: DCF EV (reference, from DCF!F14) | F37: =DCF!F14 -> 2685974
B38: Residual (rounding / unidentified) | F38: =F37-F36 -> 0

Sheet DCF
B2: Discounted Cash Flow
B3: Three horizons. EV at 2026 = PV of projected UFCF + PV of terminal value.
B5: Year | C5: 2026 | D5: 2027 | E5: 2028 | F5: 2029 | G5: 2030 | H5: 2031 | I5: 2032 | J5: 2033 | K5: 2034 | L5: 2035 | M5: 2036 | N5: 2037 | O5: 2038 | P5: 2039 | Q5: 2040 | R5: 2041 | S5: 2042 | T5: 2043 | U5: 2044 | V5: 2045
B6: Period (t, from 2026) | C6: 1 | D6: 2 | E6: 3 | F6: 4 | G6: 5 | H6: 6 | I6: 7 | J6: 8 | K6: 9 | L6: 10 | M6: 11 | N6: 12 | O6: 13 | P6: 14 | Q6: 15 | R6: 16 | S6: 17 | T6: 18 | U6: 19 | V6: 20
B7: UFCF ($M, prob-weighted) | C7: ='P&L_Consolidated'!C52 -> 10001.628 | D7: ='P&L_Consolidated'!D52 -> 14853.238 | E7: ='P&L_Consolidated'!E52 -> 22190.225 | F7: ='P&L_Consolidated'!F52 -> 33361.11 | G7: ='P&L_Consolidated'!G52 -> 50494.52 | H7: ='P&L_Consolidated'!H52 -> 67758.755 | I7: ='P&L_Consolidated'!I52 -> 91324.912 | J7: ='P&L_Consolidated'!J52 -> 123992.55 | ... V7: ='P&L_Consolidated'!V52 -> 1887737.3
B8: Discount factor at WACC | C8: =1/(1+Assumptions!$C$15)^C6 -> 0.91739963 | D8: =1/(1+Assumptions!$C$15)^D6 -> 0.84162208 | E8: =1/(1+Assumptions!$C$15)^E6 -> 0.77210379 | F8: =1/(1+Assumptions!$C$15)^F6 -> 0.70832773 | G8: =1/(1+Assumptions!$C$15)^G6 -> 0.6498196 | H8: =1/(1+Assumptions!$C$15)^H6 -> 0.59614426 | I8: =1/(1+Assumptions!$C$15)^I6 -> 0.54690252 | J8: =1/(1+Assumptions!$C$15)^J6 -> 0.50172817 | ... V8: =1/(1+Assumptions!$C$15)^V6 -> 0.17830816
B9: PV of UFCF ($M) | C9: =C7*C8 -> 9175.4897 | D9: =D7*D8 -> 12500.813 | E9: =E7*E8 -> 17133.156 | F9: =F7*F8 -> 23630.599 | G9: =G7*G8 -> 32812.328 | H9: =H7*H8 -> 40393.993 | I9: =I7*I8 -> 49945.825 | J9: =J7*J8 -> 62210.557 | ... V9: =V7*V8 -> 336598.97
B11: Enterprise value by horizon ($M)
B12: Horizon | C12: Years modeled | D12: PV of UFCFs ($M) | E12: Terminal value (PV, $M) | F12: Enterprise Value ($M)
B13: 5-year | C13: 2026-2030 | D13: =SUM(C53:G53) -> 106628.21 | E13: =(G52*(1+Assumptions!$C$16)/(Assumptions!$C$15-Assumptions!$C$16))*G8 -> 733829.97 | F13: =D13+E13 -> 840458.19
B14: 10-year | C14: 2026-2035 | D14: =SUM(C53:L53) -> 463446.04 | E14: =(L52*(1+Assumptions!$C$16)/(Assumptions!$C$15-Assumptions!$C$16))*L8 -> 2222528 | F14: =D14+E14 -> 2685974
B15: 20-year | C15: 2026-2045 | D15: =SUM(C53:V53) -> 2597483.2 | E15: =(V52*(1+Assumptions!$C$16)/(Assumptions!$C$15-Assumptions!$C$16))*V8 -> 7593983.1 | F15: =D15+E15 -> 10191466
B17: Enterprise → equity bridge ($M, except per share)
B18: Horizon | C18: EV ($M) | D18: Less: Net debt | E18: Equity value ($M) | F18: Per share ($)
B19: 5-year | C19: =F13 -> 840458.19 | D19: =Assumptions!$C$22 -> 13259 | E19: =C19-D19 -> 827199.19 | F19: =E19/Assumptions!$C$25 -> 61.731282
B20: 10-year | C20: =F14 -> 2685974 | D20: =Assumptions!$C$22 -> 13259 | E20: =C20-D20 -> 2672715 | F20: =E20/Assumptions!$C$25 -> 199.45634
B21: 20-year | C21: =F15 -> 10191466 | D21: =Assumptions!$C$22 -> 13259 | E21: =C21-D21 -> 10178207 | F21: =E21/Assumptions!$C$25 -> 759.56771
B23: Sensitivity: 10-year horizon Equity per share — WACC vs Terminal growth (centred on base case WACC 9.0% × g 4.0%, highlighted)
B24: WACC ↓ / Terminal g → | C24: 0.03 | D24: 0.035 | E24: 0.04 | F24: 0.045 | G24: 0.05
B25: 0.075 | C25: =($C$52/(1+$B25)^1+$D$52/(1+$B25)^2+$E$52/(1+$B25)^3+$F$52/(1+$B25)^4+$G$52/(1+$B25)^5+$H$52/(1+$B25)^6+$I$52/(1+$B25)^7+$J$52/(1+$B25)^8+$K$52/(1+$B25)^9+$L$52/(1+$B25)^10+$L$52*(1+C$24)/($B25-C$24)/(1+$B25)^10-Assumptions!$C$22)/Assumptions!$C$25 -> 247.1886 | D25: =($C$52/(1+$B25)^1+$D$52/(1+$B25)^2+$E$52/(1+$B25)^3+$F$52/(1+$B25)^4+$G$52/(1+$B25)^5+$H$52/(1+$B25)^6+$I$52/(1+$B25)^7+$J$52/(1+$B25)^8+$K$52/(1+$B25)^9+$L$52/(1+$B25)^10+$L$52*(1+D$24)/($B25-D$24)/(1+$B25)^10-Assumptions!$C$22)/Assumptions!$C$25 -> 274.56904 | E25: =($C$52/(1+$B25)^1+$D$52/(1+$B25)^2+$E$52/(1+$B25)^3+$F$52/(1+$B25)^4+$G$52/(1+$B25)^5+$H$52/(1+$B25)^6+$I$52/(1+$B25)^7+$J$52/(1+$B25)^8+$K$52/(1+$B25)^9+$L$52/(1+$B25)^10+$L$52*(1+E$24)/($B25-E$24)/(1+$B25)^10-Assumptions!$C$22)/Assumptions!$C$25 -> 309.77247 | F25: =($C$52/(1+$B25)^1+$D$52/(1+$B25)^2+$E$52/(1+$B25)^3+$F$52/(1+$B25)^4+$G$52/(1+$B25)^5+$H$52/(1+$B25)^6+$I$52/(1+$B25)^7+$J$52/(1+$B25)^8+$K$52/(1+$B25)^9+$L$52/(1+$B25)^10+$L$52*(1+F$24)/($B25-F$24)/(1+$B25)^10-Assumptions!$C$22)/Assumptions!$C$25 -> 356.71036 | G25: =($C$52/(1+$B25)^1+$D$52/(1+$B25)^2+$E$52/(1+$B25)^3+$F$52/(1+$B25)^4+$G$52/(1+$B25)^5+$H$52/(1+$B25)^6+$I$52/(1+$B25)^7+$J$52/(1+$B25)^8+$K$52/(1+$B25)^9+$L$52/(1+$B25)^10+$L$52*(1+G$24)/($B25-G$24)/(1+$B25)^10-Assumptions!$C$22)/Assumptions!$C$25 -> 422.42342
B26: 0.0825 | C26: =($C$52/(1+$B26)^1+$D$52/(1+$B26)^2+$E$52/(1+$B26)^3+$F$52/(1+$B26)^4+$G$52/(1+$B26)^5+$H$52/(1+$B26)^6+$I$52/(1+$B26)^7+$J$52/(1+$B26)^8+$K$52/(1+$B26)^9+$L$52/(1+$B26)^10+$L$52*(1+C$24)/($B26-C$24)/(1+$B26)^10-Assumptions!$C$22)/Assumptions!$C$25 -> 203.21065 | D26: =($C$52/(1+$B26)^1+$D$52/(1+$B26)^2+$E$52/(1+$B26)^3+$F$52/(1+$B26)^4+$G$52/(1+$B26)^5+$H$52/(1+$B26)^6+$I$52/(1+$B26)^7+$J$52/(1+$B26)^8+$K$52/(1+$B26)^9+$L$52/(1+$B26)^10+$L$52*(1+D$24)/($B26-D$24)/(1+$B26)^10-Assumptions!$C$22)/Assumptions!$C$25 -> 221.77522 | E26: =($C$52/(1+$B26)^1+$D$52/(1+$B26)^2+$E$52/(1+$B26)^3+$F$52/(1+$B26)^4+$G$52/(1+$B26)^5+$H$52/(1+$B26)^6+$I$52/(1+$B26)^7+$J$52/(1+$B26)^8+$K$52/(1+$B26)^9+$L$52/(1+$B26)^10+$L$52*(1+E$24)/($B26-E$24)/(1+$B26)^10-Assumptions!$C$22)/Assumptions!$C$25 -> 244.70793 | F26: =($C$52/(1+$B26)^1+$D$52/(1+$B26)^2+$E$52/(1+$B26)^3+$F$52/(1+$B26)^4+$G$52/(1+$B26)^5+$H$52/(1+$B26)^6+$I$52/(1+$B26)^7+$J$52/(1+$B26)^8+$K$52/(1+$B26)^9+$L$52/(1+$B26)^10+$L$52*(1+F$24)/($B26-F$24)/(1+$B26)^10-Assumptions!$C$22)/Assumptions!$C$25 -> 273.75603 | G26: =($C$52/(1+$B26)^1+$D$52/(1+$B26)^2+$E$52/(1+$B26)^3+$F$52/(1+$B26)^4+$G$52/(1+$B26)^5+$H$52/(1+$B26)^6+$I$52/(1+$B26)^7+$J$52/(1+$B26)^8+$K$52/(1+$B26)^9+$L$52/(1+$B26)^10+$L$52*(1+G$24)/($B26-G$24)/(1+$B26)^10-Assumptions!$C$22)/Assumptions!$C$25 -> 311.74201
B27: 0.09 | C27: =($C$52/(1+$B27)^1+$D$52/(1+$B27)^2+$E$52/(1+$B27)^3+$F$52/(1+$B27)^4+$G$52/(1+$B27)^5+$H$52/(1+$B27)^6+$I$52/(1+$B27)^7+$J$52/(1+$B27)^8+$K$52/(1+$B27)^9+$L$52/(1+$B27)^10+$L$52*(1+C$24)/($B27-C$24)/(1+$B27)^10-Assumptions!$C$22)/Assumptions!$C$25 -> 170.64245 | D27: =($C$52/(1+$B27)^1+$D$52/(1+$B27)^2+$E$52/(1+$B27)^3+$F$52/(1+$B27)^4+$G$52/(1+$B27)^5+$H$52/(1+$B27)^6+$I$52/(1+$B27)^7+$J$52/(1+$B27)^8+$K$52/(1+$B27)^9+$L$52/(1+$B27)^10+$L$52*(1+D$24)/($B27-D$24)/(1+$B27)^10-Assumptions!$C$22)/Assumptions!$C$25 -> 183.82613 | E27: =($C$52/(1+$B27)^1+$D$52/(1+$B27)^2+$E$52/(1+$B27)^3+$F$52/(1+$B27)^4+$G$52/(1+$B27)^5+$H$52/(1+$B27)^6+$I$52/(1+$B27)^7+$J$52/(1+$B27)^8+$K$52/(1+$B27)^9+$L$52/(1+$B27)^10+$L$52*(1+E$24)/($B27-E$24)/(1+$B27)^10-Assumptions!$C$22)/Assumptions!$C$25 -> 199.64655 | F27: =($C$52/(1+$B27)^1+$D$52/(1+$B27)^2+$E$52/(1+$B27)^3+$F$52/(1+$B27)^4+$G$52/(1+$B27)^5+$H$52/(1+$B27)^6+$I$52/(1+$B27)^7+$J$52/(1+$B27)^8+$K$52/(1+$B27)^9+$L$52/(1+$B27)^10+$L$52*(1+F$24)/($B27-F$24)/(1+$B27)^10-Assumptions!$C$22)/Assumptions!$C$25 -> 218.98262 | G27: =($C$52/(1+$B27)^1+$D$52/(1+$B27)^2+$E$52/(1+$B27)^3+$F$52/(1+$B27)^4+$G$52/(1+$B27)^5+$H$52/(1+$B27)^6+$I$52/(1+$B27)^7+$J$52/(1+$B27)^8+$K$52/(1+$B27)^9+$L$52/(1+$B27)^10+$L$52*(1+G$24)/($B27-G$24)/(1+$B27)^10-Assumptions!$C$22)/Assumptions!$C$25 -> 243.1527
B28: 0.0975 | C28: =($C$52/(1+$B28)^1+$D$52/(1+$B28)^2+$E$52/(1+$B28)^3+$F$52/(1+$B28)^4+$G$52/(1+$B28)^5+$H$52/(1+$B28)^6+$I$52/(1+$B28)^7+$J$52/(1+$B28)^8+$K$52/(1+$B28)^9+$L$52/(1+$B28)^10+$L$52*(1+C$24)/($B28-C$24)/(1+$B28)^10-Assumptions!$C$22)/Assumptions!$C$25 -> 145.65694 | D28: =($C$52/(1+$B28)^1+$D$52/(1+$B28)^2+$E$52/(1+$B28)^3+$F$52/(1+$B28)^4+$G$52/(1+$B28)^5+$H$52/(1+$B28)^6+$I$52/(1+$B28)^7+$J$52/(1+$B28)^8+$K$52/(1+$B28)^9+$L$52/(1+$B28)^10+$L$52*(1+D$24)/($B28-D$24)/(1+$B28)^10-Assumptions!$C$22)/Assumptions!$C$25 -> 155.35231 | E28: =($C$52/(1+$B28)^1+$D$52/(1+$B28)^2+$E$52/(1+$B28)^3+$F$52/(1+$B28)^4+$G$52/(1+$B28)^5+$H$52/(1+$B28)^6+$I$52/(1+$B28)^7+$J$52/(1+$B28)^8+$K$52/(1+$B28)^9+$L$52/(1+$B28)^10+$L$52*(1+E$24)/($B28-E$24)/(1+$B28)^10-Assumptions!$C$22)/Assumptions!$C$25 -> 166.73383 | F28: =($C$52/(1+$B28)^1+$D$52/(1+$B28)^2+$E$52/(1+$B28)^3+$F$52/(1+$B28)^4+$G$52/(1+$B28)^5+$H$52/(1+$B28)^6+$I$52/(1+$B28)^7+$J$52/(1+$B28)^8+$K$52/(1+$B28)^9+$L$52/(1+$B28)^10+$L$52*(1+F$24)/($B28-F$24)/(1+$B28)^10-Assumptions!$C$22)/Assumptions!$C$25 -> 180.28327 | G28: =($C$52/(1+$B28)^1+$D$52/(1+$B28)^2+$E$52/(1+$B28)^3+$F$52/(1+$B28)^4+$G$52/(1+$B28)^5+$H$52/(1+$B28)^6+$I$52/(1+$B28)^7+$J$52/(1+$B28)^8+$K$52/(1+$B28)^9+$L$52/(1+$B28)^10+$L$52*(1+G$24)/($B28-G$24)/(1+$B28)^10-Assumptions!$C$22)/Assumptions!$C$25 -> 196.68522
B29: 0.105 | C29: =($C$52/(1+$B29)^1+$D$52/(1+$B29)^2+$E$52/(1+$B29)^3+$F$52/(1+$B29)^4+$G$52/(1+$B29)^5+$H$52/(1+$B29)^6+$I$52/(1+$B29)^7+$J$52/(1+$B29)^8+$K$52/(1+$B29)^9+$L$52/(1+$B29)^10+$L$52*(1+C$24)/($B29-C$24)/(1+$B29)^10-Assumptions!$C$22)/Assumptions!$C$25 -> 125.95939 | D29: =($C$52/(1+$B29)^1+$D$52/(1+$B29)^2+$E$52/(1+$B29)^3+$F$52/(1+$B29)^4+$G$52/(1+$B29)^5+$H$52/(1+$B29)^6+$I$52/(1+$B29)^7+$J$52/(1+$B29)^8+$K$52/(1+$B29)^9+$L$52/(1+$B29)^10+$L$52*(1+D$24)/($B29-D$24)/(1+$B29)^10-Assumptions!$C$22)/Assumptions!$C$25 -> 133.28712 | E29: =($C$52/(1+$B29)^1+$D$52/(1+$B29)^2+$E$52/(1+$B29)^3+$F$52/(1+$B29)^4+$G$52/(1+$B29)^5+$H$52/(1+$B29)^6+$I$52/(1+$B29)^7+$J$52/(1+$B29)^8+$K$52/(1+$B29)^9+$L$52/(1+$B29)^10+$L$52*(1+E$24)/($B29-E$24)/(1+$B29)^10-Assumptions!$C$22)/Assumptions!$C$25 -> 141.74219 | F29: =($C$52/(1+$B29)^1+$D$52/(1+$B29)^2+$E$52/(1+$B29)^3+$F$52/(1+$B29)^4+$G$52/(1+$B29)^5+$H$52/(1+$B29)^6+$I$52/(1+$B29)^7+$J$52/(1+$B29)^8+$K$52/(1+$B29)^9+$L$52/(1+$B29)^10+$L$52*(1+F$24)/($B29-F$24)/(1+$B29)^10-Assumptions!$C$22)/Assumptions!$C$25 -> 151.60643 | G29: =($C$52/(1+$B29)^1+$D$52/(1+$B29)^2+$E$52/(1+$B29)^3+$F$52/(1+$B29)^4+$G$52/(1+$B29)^5+$H$52/(1+$B29)^6+$I$52/(1+$B29)^7+$J$52/(1+$B29)^8+$K$52/(1+$B29)^9+$L$52/(1+$B29)^10+$L$52*(1+G$24)/($B29-G$24)/(1+$B29)^10-Assumptions!$C$22)/Assumptions!$C$25 -> 163.26418
B31: FCF Adjustments — NOL, D&A tax shield, ΔNWC
B32: Original UFCF taxes EBITDA at 21% and has no D&A add-back or working-capital line. Below converts to proper unlevered FCF.
B34: Adjustment Drivers
B35: D&A as % of revenue (blended) | C35: 0.12
B36: NWC as % of revenue (blended) | C36: 0.03
B37: Opening NOL stock ($M) | C37: 25000
B38: NOL utilisation cap (post-TCJA) | C38: 0.8
B40: Adjustment time series
B41: Revenue ($M, from P&L) | C41: ='P&L_Consolidated'!C19 -> 56159.35 | D41: ='P&L_Consolidated'!D19 -> 80075.08 | E41: ='P&L_Consolidated'!E19 -> 115167.15 | F41: ='P&L_Consolidated'!F19 -> 167052.89 | G41: ='P&L_Consolidated'!G19 -> 244365.36 | H41: ='P&L_Consolidated'!H19 -> 330705 | I41: ='P&L_Consolidated'!I19 -> 436713.03 | J41: ='P&L_Consolidated'!J19 -> 581686.28 | ... V41: ='P&L_Consolidated'!V19 -> 8642655.9
B42: D&A = Rev × D&A% | C42: =C41*$C$35 -> 6739.122 | D42: =D41*$C$35 -> 9609.0096 | E42: =E41*$C$35 -> 13820.058 | F42: =F41*$C$35 -> 20046.347 | G42: =G41*$C$35 -> 29323.843 | H42: =H41*$C$35 -> 39684.6 | I42: =I41*$C$35 -> 52405.563 | J42: =J41*$C$35 -> 69802.353 | ... V42: =V41*$C$35 -> 1037118.7
B43: (+) D&A tax shield = D&A × tax | C43: =C42*Assumptions!$C$12 -> 1415.2156 | D43: =D42*Assumptions!$C$12 -> 2017.892 | E43: =E42*Assumptions!$C$12 -> 2902.2122 | F43: =F42*Assumptions!$C$12 -> 4209.7329 | G43: =G42*Assumptions!$C$12 -> 6158.007 | H43: =H42*Assumptions!$C$12 -> 8333.7659 | I43: =I42*Assumptions!$C$12 -> 11005.168 | J43: =J42*Assumptions!$C$12 -> 14658.494 | ... V43: =V42*Assumptions!$C$12 -> 217794.93
B44: NWC = Rev × NWC% | C44: =C41*$C$36 -> 1684.7805 | D44: =D41*$C$36 -> 2402.2524 | E44: =E41*$C$36 -> 3455.0145 | F44: =F41*$C$36 -> 5011.5868 | G44: =G41*$C$36 -> 7330.9607 | H44: =H41*$C$36 -> 9921.1499 | I44: =I41*$C$36 -> 13101.391 | J44: =J41*$C$36 -> 17450.588 | ... V44: =V41*$C$36 -> 259279.68
B45: (−) ΔNWC | C45: =-C44 -> -1684.7805 | D45: =-(D44-C44) -> -717.4719 | E45: =-(E44-D44) -> -1052.7621 | F45: =-(F44-E44) -> -1556.5723 | G45: =-(G44-F44) -> -2319.3739 | H45: =-(H44-G44) -> -2590.1892 | I45: =-(I44-H44) -> -3180.241 | J45: =-(J44-I44) -> -4349.1975 | K45: =-(K44-J44) -> -6018.8051 | ... V45: =-(V44-U44) -> -56443.978
B46: NOL opening | C46: =$C$37 -> 25000 | D46: =C50 -> 5616.7176 | E46: =D50 -> 0 | F46: =E50 -> 0 | G46: =F50 -> 0 | H46: =G50 -> 0 | I46: =H50 -> 0 | J46: =I50 -> 0 | K46: =J50 -> 0 | ... V46: =U50 -> 0
B47: EBIT = EBITDA − D&A | C47: ='P&L_Consolidated'!C35-C42 -> 24229.103 | D47: ='P&L_Consolidated'!D35-D42 -> 35128.579 | E47: ='P&L_Consolidated'!E35-E42 -> 51335.037 | F47: ='P&L_Consolidated'!F35-F42 -> 75604.323 | G47: ='P&L_Consolidated'!G35-G42 -> 112213.56 | H47: ='P&L_Consolidated'!H35-H42 -> 152166.21 | I47: ='P&L_Consolidated'!I35-I42 -> 202527.39 | J47: ='P&L_Consolidated'!J35-J42 -> 271720.12 | ... V47: ='P&L_Consolidated'!V35-V42 -> 4124192.6
B48: NOL used (min of EBIT×80%, NOL) | C48: =MAX(0,MIN(C46,MAX(0,C47)*$C$38)) -> 19383.282 | D48: =MAX(0,MIN(D46,MAX(0,D47)*$C$38)) -> 5616.7176 | E48: =MAX(0,MIN(E46,MAX(0,E47)*$C$38)) -> 0 | F48: =MAX(0,MIN(F46,MAX(0,F47)*$C$38)) -> 0 | G48: =MAX(0,MIN(G46,MAX(0,G47)*$C$38)) -> 0 | H48: =MAX(0,MIN(H46,MAX(0,H47)*$C$38)) -> 0 | I48: =MAX(0,MIN(I46,MAX(0,I47)*$C$38)) -> 0 | J48: =MAX(0,MIN(J46,MAX(0,J47)*$C$38)) -> 0 | ... V48: =MAX(0,MIN(V46,MAX(0,V47)*$C$38)) -> 0
...

Sheet Sensitivities
A1: SENSITIVITY TABLES
A2: All tables centred on base case (WACC 9.0%, g 4.0%). Tables 1 & 2 show the BLENDED equity (55% × 5yr + 35% × 10yr + 10% × 20yr) — consistent with Summary!E10.
A4: Table 1: Blended Enterprise Value ($M) — WACC × Terminal Growth (base highlighted)
B6: g → | C6: 0.03 | D6: 0.035 | E6: 0.04 | F6: 0.045 | G6: 0.05
B7: WACC ↓
B8: 0.075 | C8: {=Assumptions!$C$35*(SUMPRODUCT(DCF!$C$52:$G$52,1/(1+$B8)^{1,2,3,4,5})+DCF!$G$52*(1+C$6)/($B8-C$6)/(1+$B8)^5)+Assumptions!$C$36*(SUMPRODUCT(DCF!$C$52:$L$52,1/(1+$B8)^{1,2,3,4,5,6,7,8,9,10})+DCF!$L$52*(1+C$6)/($B8-C$6)/(1+$B8)^10)+Assumptions!$C$37*(SUMPRODUCT(DCF!$C$52:$V$52,1/(1+$B8)^{1,2,3,4,5,6,7,8,9,10,11,12,13,14,15,16,17,18,19,20})+DCF!$V$52*(1+C$6)/($B8-C$6)/(1+$B8)^20)} -> 3126104.9 | D8: {=Assumptions!$C$35*(SUMPRODUCT(DCF!$C$52:$G$52,1/(1+$B8)^{1,2,3,4,5})+DCF!$G$52*(1+D$6)/($B8-D$6)/(1+$B8)^5)+Assumptions!$C$36*(SUMPRODUCT(DCF!$C$52:$L$52,1/(1+$B8)^{1,2,3,4,5,6,7,8,9,10})+DCF!$L$52*(1+D$6)/($B8-D$6)/(1+$B8)^10)+Assumptions!$C$37*(SUMPRODUCT(DCF!$C$52:$V$52,1/(1+$B8)^{1,2,3,4,5,6,7,8,9,10,11,12,13,14,15,16,17,18,19,20})+DCF!$V$52*(1+D$6)/($B8-D$6)/(1+$B8)^20)} -> 3460721.1 | E8: {=Assumptions!$C$35*(SUMPRODUCT(DCF!$C$52:$G$52,1/(1+$B8)^{1,2,3,4,5})+DCF!$G$52*(1+E$6)/($B8-E$6)/(1+$B8)^5)+Assumptions!$C$36*(SUMPRODUCT(DCF!$C$52:$L$52,1/(1+$B8)^{1,2,3,4,5,6,7,8,9,10})+DCF!$L$52*(1+E$6)/($B8-E$6)/(1+$B8)^10)+Assumptions!$C$37*(SUMPRODUCT(DCF!$C$52:$V$52,1/(1+$B8)^{1,2,3,4,5,6,7,8,9,10,11,12,13,14,15,16,17,18,19,20})+DCF!$V$52*(1+E$6)/($B8-E$6)/(1+$B8)^20)} -> 3890941.8 | F8: {=Assumptions!$C$35*(SUMPRODUCT(DCF!$C$52:$G$52,1/(1+$B8)^{1,2,3,4,5})+DCF!$G$52*(1+F$6)/($B8-F$6)/(1+$B8)^5)+Assumptions!$C$36*(SUMPRODUCT(DCF!$C$52:$L$52,1/(1+$B8)^{1,2,3,4,5,6,7,8,9,10})+DCF!$L$52*(1+F$6)/($B8-F$6)/(1+$B8)^10)+Assumptions!$C$37*(SUMPRODUCT(DCF!$C$52:$V$52,1/(1+$B8)^{1,2,3,4,5,6,7,8,9,10,11,12,13,14,15,16,17,18,19,20})+DCF!$V$52*(1+F$6)/($B8-F$6)/(1+$B8)^20)} -> 4464569.5 | G8: {=Assumptions!$C$35*(SUMPRODUCT(DCF!$C$52:$G$52,1/(1+$B8)^{1,2,3,4,5})+DCF!$G$52*(1+G$6)/($B8-G$6)/(1+$B8)^5)+Assumptions!$C$36*(SUMPRODUCT(DCF!$C$52:$L$52,1/(1+$B8)^{1,2,3,4,5,6,7,8,9,10})+DCF!$L$52*(1+G$6)/($B8-G$6)/(1+$B8)^10)+Assumptions!$C$37*(SUMPRODUCT(DCF!$C$52:$V$52,1/(1+$B8)^{1,2,3,4,5,6,7,8,9,10,11,12,13,14,15,16,17,18,19,20})+DCF!$V$52*(1+G$6)/($B8-G$6)/(1+$B8)^20)} -> 5267648.3
B9: 0.0825 | C9: {=Assumptions!$C$35*(SUMPRODUCT(DCF!$C$52:$G$52,1/(1+$B9)^{1,2,3,4,5})+DCF!$G$52*(1+C$6)/($B9-C$6)/(1+$B9)^5)+Assumptions!$C$36*(SUMPRODUCT(DCF!$C$52:$L$52,1/(1+$B9)^{1,2,3,4,5,6,7,8,9,10})+DCF!$L$52*(1+C$6)/($B9-C$6)/(1+$B9)^10)+Assumptions!$C$37*(SUMPRODUCT(DCF!$C$52:$V$52,1/(1+$B9)^{1,2,3,4,5,6,7,8,9,10,11,12,13,14,15,16,17,18,19,20})+DCF!$V$52*(1+C$6)/($B9-C$6)/(1+$B9)^20)} -> 2523892.3 | D9: {=Assumptions!$C$35*(SUMPRODUCT(DCF!$C$52:$G$52,1/(1+$B9)^{1,2,3,4,5})+DCF!$G$52*(1+D$6)/($B9-D$6)/(1+$B9)^5)+Assumptions!$C$36*(SUMPRODUCT(DCF!$C$52:$L$52,1/(1+$B9)^{1,2,3,4,5,6,7,8,9,10})+DCF!$L$52*(1+D$6)/($B9-D$6)/(1+$B9)^10)+Assumptions!$C$37*(SUMPRODUCT(DCF!$C$52:$V$52,1/(1+$B9)^{1,2,3,4,5,6,7,8,9,10,11,12,13,14,15,16,17,18,19,20})+DCF!$V$52*(1+D$6)/($B9-D$6)/(1+$B9)^20)} -> 2745701.1 | E9: {=Assumptions!$C$35*(SUMPRODUCT(DCF!$C$52:$G$52,1/(1+$B9)^{1,2,3,4,5})+DCF!$G$52*(1+E$6)/($B9-E$6)/(1+$B9)^5)+Assumptions!$C$36*(SUMPRODUCT(DCF!$C$52:$L$52,1/(1+$B9)^{1,2,3,4,5,6,7,8,9,10})+DCF!$L$52*(1+E$6)/($B9-E$6)/(1+$B9)^10)+Assumptions!$C$37*(SUMPRODUCT(DCF!$C$52:$V$52,1/(1+$B9)^{1,2,3,4,5,6,7,8,9,10,11,12,13,14,15,16,17,18,19,20})+DCF!$V$52*(1+E$6)/($B9-E$6)/(1+$B9)^20)} -> 3019700.2 | F9: {=Assumptions!$C$35*(SUMPRODUCT(DCF!$C$52:$G$52,1/(1+$B9)^{1,2,3,4,5})+DCF!$G$52*(1+F$6)/($B9-F$6)/(1+$B9)^5)+Assumptions!$C$36*(SUMPRODUCT(DCF!$C$52:$L$52,1/(1+$B9)^{1,2,3,4,5,6,7,8,9,10})+DCF!$L$52*(1+F$6)/($B9-F$6)/(1+$B9)^10)+Assumptions!$C$37*(SUMPRODUCT(DCF!$C$52:$V$52,1/(1+$B9)^{1,2,3,4,5,6,7,8,9,10,11,12,13,14,15,16,17,18,19,20})+DCF!$V$52*(1+F$6)/($B9-F$6)/(1+$B9)^20)} -> 3366765.7 | G9: {=Assumptions!$C$35*(SUMPRODUCT(DCF!$C$52:$G$52,1/(1+$B9)^{1,2,3,4,5})+DCF!$G$52*(1+G$6)/($B9-G$6)/(1+$B9)^5)+Assumptions!$C$36*(SUMPRODUCT(DCF!$C$52:$L$52,1/(1+$B9)^{1,2,3,4,5,6,7,8,9,10})+DCF!$L$52*(1+G$6)/($B9-G$6)/(1+$B9)^10)+Assumptions!$C$37*(SUMPRODUCT(DCF!$C$52:$V$52,1/(1+$B9)^{1,2,3,4,5,6,7,8,9,10,11,12,13,14,15,16,17,18,19,20})+DCF!$V$52*(1+G$6)/($B9-G$6)/(1+$B9)^20)} -> 3820620.6
B10: 0.09 | C10: {=Assumptions!$C$35*(SUMPRODUCT(DCF!$C$52:$G$52,1/(1+$B10)^{1,2,3,4,5})+DCF!$G$52*(1+C$6)/($B10-C$6)/(1+$B10)^5)+Assumptions!$C$36*(SUMPRODUCT(DCF!$C$52:$L$52,1/(1+$B10)^{1,2,3,4,5,6,7,8,9,10})+DCF!$L$52*(1+C$6)/($B10-C$6)/(1+$B10)^10)+Assumptions!$C$37*(SUMPRODUCT(DCF!$C$52:$V$52,1/(1+$B10)^{1,2,3,4,5,6,7,8,9,10,11,12,13,14,15,16,17,18,19,20})+DCF!$V$52*(1+C$6)/($B10-C$6)/(1+$B10)^20)} -> 2084548.4 | D10: {=Assumptions!$C$35*(SUMPRODUCT(DCF!$C$52:$G$52,1/(1+$B10)^{1,2,3,4,5})+DCF!$G$52*(1+D$6)/($B10-D$6)/(1+$B10)^5)+Assumptions!$C$36*(SUMPRODUCT(DCF!$C$52:$L$52,1/(1+$B10)^{1,2,3,4,5,6,7,8,9,10})+DCF!$L$52*(1+D$6)/($B10-D$6)/(1+$B10)^10)+Assumptions!$C$37*(SUMPRODUCT(DCF!$C$52:$V$52,1/(1+$B10)^{1,2,3,4,5,6,7,8,9,10,11,12,13,14,15,16,17,18,19,20})+DCF!$V$52*(1+D$6)/($B10-D$6)/(1+$B10)^20)} -> 2238838.4 | E10: {=Assumptions!$C$35*(SUMPRODUCT(DCF!$C$52:$G$52,1/(1+$B10)^{1,2,3,4,5})+DCF!$G$52*(1+E$6)/($B10-E$6)/(1+$B10)^5)+Assumptions!$C$36*(SUMPRODUCT(DCF!$C$52:$L$52,1/(1+$B10)^{1,2,3,4,5,6,7,8,9,10})+DCF!$L$52*(1+E$6)/($B10-E$6)/(1+$B10)^10)+Assumptions!$C$37*(SUMPRODUCT(DCF!$C$52:$V$52,1/(1+$B10)^{1,2,3,4,5,6,7,8,9,10,11,12,13,14,15,16,17,18,19,20})+DCF!$V$52*(1+E$6)/($B10-E$6)/(1+$B10)^20)} -> 2423986.5 | F10: {=Assumptions!$C$35*(SUMPRODUCT(DCF!$C$52:$G$52,1/(1+$B10)^{1,2,3,4,5})+DCF!$G$52*(1+F$6)/($B10-F$6)/(1+$B10)^5)+Assumptions!$C$36*(SUMPRODUCT(DCF!$C$52:$L$52,1/(1+$B10)^{1,2,3,4,5,6,7,8,9,10})+DCF!$L$52*(1+F$6)/($B10-F$6)/(1+$B10)^10)+Assumptions!$C$37*(SUMPRODUCT(DCF!$C$52:$V$52,1/(1+$B10)^{1,2,3,4,5,6,7,8,9,10,11,12,13,14,15,16,17,18,19,20})+DCF!$V$52*(1+F$6)/($B10-F$6)/(1+$B10)^20)} -> 2650278.6 | G10: {=Assumptions!$C$35*(SUMPRODUCT(DCF!$C$52:$G$52,1/(1+$B10)^{1,2,3,4,5})+DCF!$G$52*(1+G$6)/($B10-G$6)/(1+$B10)^5)+Assumptions!$C$36*(SUMPRODUCT(DCF!$C$52:$L$52,1/(1+$B10)^{1,2,3,4,5,6,7,8,9,10})+DCF!$L$52*(1+G$6)/($B10-G$6)/(1+$B10)^10)+Assumptions!$C$37*(SUMPRODUCT(DCF!$C$52:$V$52,1/(1+$B10)^{1,2,3,4,5,6,7,8,9,10,11,12,13,14,15,16,17,18,19,20})+DCF!$V$52*(1+G$6)/($B10-G$6)/(1+$B10)^20)} -> 2933143.8
B11: 0.0975 | C11: {=Assumptions!$C$35*(SUMPRODUCT(DCF!$C$52:$G$52,1/(1+$B11)^{1,2,3,4,5})+DCF!$G$52*(1+C$6)/($B11-C$6)/(1+$B11)^5)+Assumptions!$C$36*(SUMPRODUCT(DCF!$C$52:$L$52,1/(1+$B11)^{1,2,3,4,5,6,7,8,9,10})+DCF!$L$52*(1+C$6)/($B11-C$6)/(1+$B11)^10)+Assumptions!$C$37*(SUMPRODUCT(DCF!$C$52:$V$52,1/(1+$B11)^{1,2,3,4,5,6,7,8,9,10,11,12,13,14,15,16,17,18,19,20})+DCF!$V$52*(1+C$6)/($B11-C$6)/(1+$B11)^20)} -> 1752599.2 | D11: {=Assumptions!$C$35*(SUMPRODUCT(DCF!$C$52:$G$52,1/(1+$B11)^{1,2,3,4,5})+DCF!$G$52*(1+D$6)/($B11-D$6)/(1+$B11)^5)+Assumptions!$C$36*(SUMPRODUCT(DCF!$C$52:$L$52,1/(1+$B11)^{1,2,3,4,5,6,7,8,9,10})+DCF!$L$52*(1+D$6)/($B11-D$6)/(1+$B11)^10)+Assumptions!$C$37*(SUMPRODUCT(DCF!$C$52:$V$52,1/(1+$B11)^{1,2,3,4,5,6,7,8,9,10,11,12,13,14,15,16,17,18,19,20})+DCF!$V$52*(1+D$6)/($B11-D$6)/(1+$B11)^20)} -> 1863945.1 | E11: {=Assumptions!$C$35*(SUMPRODUCT(DCF!$C$52:$G$52,1/(1+$B11)^{1,2,3,4,5})+DCF!$G$52*(1+E$6)/($B11-E$6)/(1+$B11)^5)+Assumptions!$C$36*(SUMPRODUCT(DCF!$C$52:$L$52,1/(1+$B11)^{1,2,3,4,5,6,7,8,9,10})+DCF!$L$52*(1+E$6)/($B11-E$6)/(1+$B11)^10)+Assumptions!$C$37*(SUMPRODUCT(DCF!$C$52:$V$52,1/(1+$B11)^{1,2,3,4,5,6,7,8,9,10,11,12,13,14,15,16,17,18,19,20})+DCF!$V$52*(1+E$6)/($B11-E$6)/(1+$B11)^20)} -> 1994655.5 | F11: {=Assumptions!$C$35*(SUMPRODUCT(DCF!$C$52:$G$52,1/(1+$B11)^{1,2,3,4,5})+DCF!$G$52*(1+F$6)/($B11-F$6)/(1+$B11)^5)+Assumptions!$C$36*(SUMPRODUCT(DCF!$C$52:$L$52,1/(1+$B11)^{1,2,3,4,5,6,7,8,9,10})+DCF!$L$52*(1+F$6)/($B11-F$6)/(1+$B11)^10)+Assumptions!$C$37*(SUMPRODUCT(DCF!$C$52:$V$52,1/(1+$B11)^{1,2,3,4,5,6,7,8,9,10,11,12,13,14,15,16,17,18,19,20})+DCF!$V$52*(1+F$6)/($B11-F$6)/(1+$B11)^20)} -> 2150263.1 | G11: {=Assumptions!$C$35*(SUMPRODUCT(DCF!$C$52:$G$52,1/(1+$B11)^{1,2,3,4,5})+DCF!$G$52*(1+G$6)/($B11-G$6)/(1+$B11)^5)+Assumptions!$C$36*(SUMPRODUCT(DCF!$C$52:$L$52,1/(1+$B11)^{1,2,3,4,5,6,7,8,9,10})+DCF!$L$52*(1+G$6)/($B11-G$6)/(1+$B11)^10)+Assumptions!$C$37*(SUMPRODUCT(DCF!$C$52:$V$52,1/(1+$B11)^{1,2,3,4,5,6,7,8,9,10,11,12,13,14,15,16,17,18,19,20})+DCF!$V$52*(1+G$6)/($B11-G$6)/(1+$B11)^20)} -> 2338630.2
B12: 0.105 | C12: {=Assumptions!$C$35*(SUMPRODUCT(DCF!$C$52:$G$52,1/(1+$B12)^{1,2,3,4,5})+DCF!$G$52*(1+C$6)/($B12-C$6)/(1+$B12)^5)+Assumptions!$C$36*(SUMPRODUCT(DCF!$C$52:$L$52,1/(1+$B12)^{1,2,3,4,5,6,7,8,9,10})+DCF!$L$52*(1+C$6)/($B12-C$6)/(1+$B12)^10)+Assumptions!$C$37*(SUMPRODUCT(DCF!$C$52:$V$52,1/(1+$B12)^{1,2,3,4,5,6,7,8,9,10,11,12,13,14,15,16,17,18,19,20})+DCF!$V$52*(1+C$6)/($B12-C$6)/(1+$B12)^20)} -> 1494889.6 | D12: {=Assumptions!$C$35*(SUMPRODUCT(DCF!$C$52:$G$52,1/(1+$B12)^{1,2,3,4,5})+DCF!$G$52*(1+D$6)/($B12-D$6)/(1+$B12)^5)+Assumptions!$C$36*(SUMPRODUCT(DCF!$C$52:$L$52,1/(1+$B12)^{1,2,3,4,5,6,7,8,9,10})+DCF!$L$52*(1+D$6)/($B12-D$6)/(1+$B12)^10)+Assumptions!$C$37*(SUMPRODUCT(DCF!$C$52:$V$52,1/(1+$B12)^{1,2,3,4,5,6,7,8,9,10,11,12,13,14,15,16,17,18,19,20})+DCF!$V$52*(1+D$6)/($B12-D$6)/(1+$B12)^20)} -> 1577620.3 | E12: {=Assumptions!$C$35*(SUMPRODUCT(DCF!$C$52:$G$52,1/(1+$B12)^{1,2,3,4,5})+DCF!$G$52*(1+E$6)/($B12-E$6)/(1+$B12)^5)+Assumptions!$C$36*(SUMPRODUCT(DCF!$C$52:$L$52,1/(1+$B12)^{1,2,3,4,5,6,7,8,9,10})+DCF!$L$52*(1+E$6)/($B12-E$6)/(1+$B12)^10)+Assumptions!$C$37*(SUMPRODUCT(DCF!$C$52:$V$52,1/(1+$B12)^{1,2,3,4,5,6,7,8,9,10,11,12,13,14,15,16,17,18,19,20})+DCF!$V$52*(1+E$6)/($B12-E$6)/(1+$B12)^20)} -> 1673078.8 | F12: {=Assumptions!$C$35*(SUMPRODUCT(DCF!$C$52:$G$52,1/(1+$B12)^{1,2,3,4,5})+DCF!$G$52*(1+F$6)/($B12-F$6)/(1+$B12)^5)+Assumptions!$C$36*(SUMPRODUCT(DCF!$C$52:$L$52,1/(1+$B12)^{1,2,3,4,5,6,7,8,9,10})+DCF!$L$52*(1+F$6)/($B12-F$6)/(1+$B12)^10)+Assumptions!$C$37*(SUMPRODUCT(DCF!$C$52:$V$52,1/(1+$B12)^{1,2,3,4,5,6,7,8,9,10,11,12,13,14,15,16,17,18,19,20})+DCF!$V$52*(1+F$6)/($B12-F$6)/(1+$B12)^20)} -> 1784447 | G12: {=Assumptions!$C$35*(SUMPRODUCT(DCF!$C$52:$G$52,1/(1+$B12)^{1,2,3,4,5})+DCF!$G$52*(1+G$6)/($B12-G$6)/(1+$B12)^5)+Assumptions!$C$36*(SUMPRODUCT(DCF!$C$52:$L$52,1/(1+$B12)^{1,2,3,4,5,6,7,8,9,10})+DCF!$L$52*(1+G$6)/($B12-G$6)/(1+$B12)^10)+Assumptions!$C$37*(SUMPRODUCT(DCF!$C$52:$V$52,1/(1+$B12)^{1,2,3,4,5,6,7,8,9,10,11,12,13,14,15,16,17,18,19,20})+DCF!$V$52*(1+G$6)/($B12-G$6)/(1+$B12)^20)} -> 1916064.1
A14: Table 2: Blended Value per Share ($) — WACC × Terminal Growth (base highlighted)
B16: g → | C16: =C6 -> 0.03 | D16: =D6 -> 0.035 | E16: =E6 -> 0.04 | F16: =F6 -> 0.045 | G16: =G6 -> 0.05
B17: WACC ↓
B18: =B8 -> 0.075 | C18: =(C8-Assumptions!$C$22)/Assumptions!$C$25 -> 232.30193 | D18: =(D8-Assumptions!$C$22)/Assumptions!$C$25 -> 257.27329 | E18: =(E8-Assumptions!$C$22)/Assumptions!$C$25 -> 289.37932 | F18: =(F8-Assumptions!$C$22)/Assumptions!$C$25 -> 332.18735 | G18: =(G8-Assumptions!$C$22)/Assumptions!$C$25 -> 392.1186
B19: =B9 -> 0.0825 | C19: =(C9-Assumptions!$C$22)/Assumptions!$C$25 -> 187.3607 | D19: =(D9-Assumptions!$C$22)/Assumptions!$C$25 -> 203.91359 | E19: =(E9-Assumptions!$C$22)/Assumptions!$C$25 -> 224.36128 | F19: =(F9-Assumptions!$C$22)/Assumptions!$C$25 -> 250.2617 | G19: =(G9-Assumptions!$C$22)/Assumptions!$C$25 -> 284.13147
B20: =B10 -> 0.09 | C20: =(C10-Assumptions!$C$22)/Assumptions!$C$25 -> 154.57383 | D20: =(D10-Assumptions!$C$22)/Assumptions!$C$25 -> 166.08802 | E20: =(E10-Assumptions!$C$22)/Assumptions!$C$25 -> 179.90504 | F20: =(F10-Assumptions!$C$22)/Assumptions!$C$25 -> 196.79251 | G20: =(G10-Assumptions!$C$22)/Assumptions!$C$25 -> 217.90185 | H20: =H10 -> 0 | I20: =I10 -> 0
B21: =B11 -> 0.0975 | C21: =(C11-Assumptions!$C$22)/Assumptions!$C$25 -> 129.80151 | D21: =(D11-Assumptions!$C$22)/Assumptions!$C$25 -> 138.1109 | E21: =(E11-Assumptions!$C$22)/Assumptions!$C$25 -> 147.86541 | F21: =(F11-Assumptions!$C$22)/Assumptions!$C$25 -> 159.47792 | G21: =(G11-Assumptions!$C$22)/Assumptions!$C$25 -> 173.53516
B22: =B12 -> 0.105 | C22: =(C12-Assumptions!$C$22)/Assumptions!$C$25 -> 110.56944 | D22: =(D12-Assumptions!$C$22)/Assumptions!$C$25 -> 116.74338 | E22: =(E12-Assumptions!$C$22)/Assumptions!$C$25 -> 123.86715 | F22: =(F12-Assumptions!$C$22)/Assumptions!$C$25 -> 132.17821 | G22: =(G12-Assumptions!$C$22)/Assumptions!$C$25 -> 142.00038
D23: =D13 -> 0
A24: Table 3: Probability-of-Success Sensitivity — SOTP Total Equity ($M) | D24: =D14 -> 0
A25: How does total equity move as we re-weight the speculative bucket? (Anchor + Plausible held constant at Base.) | D25: =D15 -> 0
D26: =D16 -> 0.035
B27: Speculative scenario | C27: Spec EV contrib ($M) | D27: Anchor+Plausible ($M) | E27: Total EV ($M) | F27: Total equity ($M) | G27: $/share
B28: All speculative zeroed out (100% failure) | C28: 0 | D28: ='Sum of Parts'!F21-SUMIFS('Sum of Parts'!$F$9:$F$20,'Sum of Parts'!$B$9:$B$20,"SPECULATIVE") -> 2230083.4 | E28: =C28+D28 -> 2230083.4 | F28: =E28-Assumptions!$C$22 -> 2216824.4 | G28: =F28/Assumptions!$C$25 -> 165.43466
B29: Bear case for speculative (current materialisation × 0.25) | C29: =SUMIFS('Sum of Parts'!$F$9:$F$20,'Sum of Parts'!$B$9:$B$20,"SPECULATIVE")*0.25 -> 6681.8536 | D29: =$D$28 -> 2230083.4 | E29: =C29+D29 -> 2236765.3 | F29: =E29-Assumptions!$C$22 -> 2223506.3 | G29: =F29/Assumptions!$C$25 -> 165.9333
B30: Base case (current model weighting) | C30: =SUMIFS('Sum of Parts'!$F$9:$F$20,'Sum of Parts'!$B$9:$B$20,"SPECULATIVE") -> 26727.414 | D30: =$D$28 -> 2230083.4 | E30: =C30+D30 -> 2256810.8 | F30: =E30-Assumptions!$C$22 -> 2243551.8 | G30: =F30/Assumptions!$C$25 -> 167.42924
B31: Bull case (current × 3, broader optionality success) | C31: =SUMIFS('Sum of Parts'!$F$9:$F$20,'Sum of Parts'!$B$9:$B$20,"SPECULATIVE")*3 -> 80182.243 | D31: =$D$28 -> 2230083.4 | E31: =C31+D31 -> 2310265.7 | F31: =E31-Assumptions!$C$22 -> 2297006.7 | G31: =F31/Assumptions!$C$25 -> 171.41841
B32: Bull-Bull (current × 10, all optionality realised) | C32: =SUMIFS('Sum of Parts'!$F$9:$F$20,'Sum of Parts'!$B$9:$B$20,"SPECULATIVE")*10 -> 267274.14 | D32: =$D$28 -> 2230083.4 | E32: =C32+D32 -> 2497357.6 | F32: =E32-Assumptions!$C$22 -> 2484098.6 | G32: =F32/Assumptions!$C$25 -> 185.38049
B34: Speculative segments full write-off VaR
B35: If both SPECULATIVE-tier segments are removed entirely (legal/physics/timeline failure), what's the value at risk?
B36: Orbital DCs current Base EV ($M) | C36: ='Sum of Parts'!F19 -> 26711.956
B37: Deep Space Optionality current Base EV ($M) | C37: ='Sum of Parts'!F20 -> 15.457795
B38: Combined speculative VaR ($M) | C38: =C36+C37 -> 26727.414
B39: Impact on $/share if both written off | C39: =-C38/Assumptions!$C$25 -> -1.9945832
A45: Table 4: SENSITIVITY TORNADO — Drivers ranked by equity impact ($Bn)
A46: Each row shows the equity impact ($Bn) of moving one driver to a downside or upside case while holding others at base. Sorted by absolute swing.
B48: Driver | C48: Downside case | D48: Upside case | E48: Downside impact ($Bn) | F48: Upside impact ($Bn) | G48: Range ($Bn) | I48: Tornado data (sorted by range descending)
B49: Base equity ($Bn) | G49: =Summary!E10/1000 -> 2408.2305 | I49: Driver | J49: Downside | K49: Upside
B50: WACC ±150bps | C50: 0.105 | D50: 0.075 | E50: =(E12-E10)/1000 -> -750.90776 | F50: =(E8-E10)/1000 -> 1466.9553 | G50: =F50-E50 -> 2217.8631 | I50: =B50 -> WACC ±150bps | J50: =E50 -> -750.90776 | K50: =F50 -> 1466.9553
B51: Terminal g ±100bps | C51: 0.03 | D51: 0.05 | E51: =(D10-E10)/1000 -> -185.14809 | F51: =(G10-E10)/1000 -> 509.15726 | G51: =F51-E51 -> 694.30535 | I51: =B52 -> Speculative bucket success | J51: =E52 -> -26.727414 | K51: =F52 -> 53.454828
...

Sheet Monte_Carlo
A1: MONTE CARLO SIMULATION — SpaceX Valuation Distribution | I1: u_WACC | J1: u_g | K1: u_anchor | L1: u_plaus | M1: u_spec | N1: EV ($M) | O1: $/share
A2: 5,000 trials. Random draws on WACC, terminal g, and 5 segment-bucket scenario outcomes. Output: equity value distribution. | I2: =MAX($D$6,MIN($E$6,_xlfn.NORM.INV(RAND(),$B$6,$C$6))) -> 0.095931609 | J2: =MAX($D$7,MIN($E$7,_xlfn.NORM.INV(RAND(),$B$7,$C$7))) -> 0.044659803 | K2: =RAND() -> 0.021136744 | L2: =RAND() -> 0.11813364 | M2: =RAND() -> 0.74083563 | N2: =(IF(K2<$E$10,$B$10,IF(K2<$E$10+$F$10,$C$10,$D$10))+IF(L2<$E$11,$B$11,IF(L2<$E$11+$F$11,$C$11,$D$11))+IF(M2<$E$12,$B$12,IF(M2<$E$12+$F$12,$C$12,$D$12)))*MIN(2.5,MAX(0.5,(0.09-0.04)/MAX(0.025,(I2-J2)))) -> 342121.51 | O2: =(N2-Assumptions!$C$22)/Assumptions!$C$25 -> 24.541978
A3: F9 = recalc (or press F9). Distribution updates live. | I3: =MAX($D$6,MIN($E$6,_xlfn.NORM.INV(RAND(),$B$6,$C$6))) -> 0.079123846 | J3: =MAX($D$7,MIN($E$7,_xlfn.NORM.INV(RAND(),$B$7,$C$7))) -> 0.041667591 | K3: =RAND() -> 0.35594137 | L3: =RAND() -> 0.61542808 | M3: =RAND() -> 0.061270816 | N3: =(IF(K3<$E$10,$B$10,IF(K3<$E$10+$F$10,$C$10,$D$10))+IF(L3<$E$11,$B$11,IF(L3<$E$11+$F$11,$C$11,$D$11))+IF(M3<$E$12,$B$12,IF(M3<$E$12+$F$12,$C$12,$D$12)))*MIN(2.5,MAX(0.5,(0.09-0.04)/MAX(0.025,(I3-J3)))) -> 2980027.5 | O3: =(N3-Assumptions!$C$22)/Assumptions!$C$25 -> 221.40063
I4: =MAX($D$6,MIN($E$6,_xlfn.NORM.INV(RAND(),$B$6,$C$6))) -> 0.11032875 | J4: =MAX($D$7,MIN($E$7,_xlfn.NORM.INV(RAND(),$B$7,$C$7))) -> 0.027101773 | K4: =RAND() -> 0.21882029 | L4: =RAND() -> 0.553015 | M4: =RAND() -> 0.65744169 | N4: =(IF(K4<$E$10,$B$10,IF(K4<$E$10+$F$10,$C$10,$D$10))+IF(L4<$E$11,$B$11,IF(L4<$E$11+$F$11,$C$11,$D$11))+IF(M4<$E$12,$B$12,IF(M4<$E$12+$F$12,$C$12,$D$12)))*MIN(2.5,MAX(0.5,(0.09-0.04)/MAX(0.025,(I4-J4)))) -> 1355816.9 | O4: =(N4-Assumptions!$C$22)/Assumptions!$C$25 -> 100.19089
A5: INPUT DISTRIBUTIONS | B5: Mean | C5: Stdev | D5: Min | E5: Max | F5: Notes | I5: =MAX($D$6,MIN($E$6,_xlfn.NORM.INV(RAND(),$B$6,$C$6))) -> 0.089944321 | J5: =MAX($D$7,MIN($E$7,_xlfn.NORM.INV(RAND(),$B$7,$C$7))) -> 0.032623461 | K5: =RAND() -> 0.16314547 | L5: =RAND() -> 0.35159069 | M5: =RAND() -> 0.49369953 | N5: =(IF(K5<$E$10,$B$10,IF(K5<$E$10+$F$10,$C$10,$D$10))+IF(L5<$E$11,$B$11,IF(L5<$E$11+$F$11,$C$11,$D$11))+IF(M5<$E$12,$B$12,IF(M5<$E$12+$F$12,$C$12,$D$12)))*MIN(2.5,MAX(0.5,(0.09-0.04)/MAX(0.025,(I5-J5)))) -> 677730.03 | O5: =(N5-Assumptions!$C$22)/Assumptions!$C$25 -> 49.58739
A6: WACC | B6: 0.09 | C6: 0.015 | D6: 0.06 | E6: 0.14 | F6: Normal truncated. Tighter ranges = more concentrated distribution. | I6: =MAX($D$6,MIN($E$6,_xlfn.NORM.INV(RAND(),$B$6,$C$6))) -> 0.07733347 | J6: =MAX($D$7,MIN($E$7,_xlfn.NORM.INV(RAND(),$B$7,$C$7))) -> 0.036915591 | K6: =RAND() -> 0.051014521 | L6: =RAND() -> 0.62082895 | M6: =RAND() -> 0.341316 | N6: =(IF(K6<$E$10,$B$10,IF(K6<$E$10+$F$10,$C$10,$D$10))+IF(L6<$E$11,$B$11,IF(L6<$E$11+$F$11,$C$11,$D$11))+IF(M6<$E$12,$B$12,IF(M6<$E$12+$F$12,$C$12,$D$12)))*MIN(2.5,MAX(0.5,(0.09-0.04)/MAX(0.025,(I6-J6)))) -> 961160.48 | O6: =(N6-Assumptions!$C$22)/Assumptions!$C$25 -> 70.738916
A7: Terminal growth | B7: 0.04 | C7: 0.01 | D7: 0.02 | E7: 0.055 | F7: Normal truncated. | I7: =MAX($D$6,MIN($E$6,_xlfn.NORM.INV(RAND(),$B$6,$C$6))) -> 0.092912354 | J7: =MAX($D$7,MIN($E$7,_xlfn.NORM.INV(RAND(),$B$7,$C$7))) -> 0.023189666 | K7: =RAND() -> 0.53468673 | L7: =RAND() -> 0.72077079 | M7: =RAND() -> 0.46133951 | N7: =(IF(K7<$E$10,$B$10,IF(K7<$E$10+$F$10,$C$10,$D$10))+IF(L7<$E$11,$B$11,IF(L7<$E$11+$F$11,$C$11,$D$11))+IF(M7<$E$12,$B$12,IF(M7<$E$12+$F$12,$C$12,$D$12)))*MIN(2.5,MAX(0.5,(0.09-0.04)/MAX(0.025,(I7-J7)))) -> 1600923.2 | O7: =(N7-Assumptions!$C$22)/Assumptions!$C$25 -> 118.4824
I8: =MAX($D$6,MIN($E$6,_xlfn.NORM.INV(RAND(),$B$6,$C$6))) -> 0.076983207 | J8: =MAX($D$7,MIN($E$7,_xlfn.NORM.INV(RAND(),$B$7,$C$7))) -> 0.032200035 | K8: =RAND() -> 0.27634448 | L8: =RAND() -> 0.46753763 | M8: =RAND() -> 0.87088995 | N8: =(IF(K8<$E$10,$B$10,IF(K8<$E$10+$F$10,$C$10,$D$10))+IF(L8<$E$11,$B$11,IF(L8<$E$11+$F$11,$C$11,$D$11))+IF(M8<$E$12,$B$12,IF(M8<$E$12+$F$12,$C$12,$D$12)))*MIN(2.5,MAX(0.5,(0.09-0.04)/MAX(0.025,(I8-J8)))) -> 2519708.6 | O8: =(N8-Assumptions!$C$22)/Assumptions!$C$25 -> 187.04848
A9: SEGMENT BUCKET SCENARIO PROBS | B9: Bear EV ($M) | C9: Base EV ($M) | D9: Bull EV ($M) | E9: P(Bear) | F9: P(Base) | G9: P(Bull) | I9: =MAX($D$6,MIN($E$6,_xlfn.NORM.INV(RAND(),$B$6,$C$6))) -> 0.088513862 | J9: =MAX($D$7,MIN($E$7,_xlfn.NORM.INV(RAND(),$B$7,$C$7))) -> 0.030132391 | K9: =RAND() -> 0.96360053 | L9: =RAND() -> 0.15016888 | M9: =RAND() -> 0.78564126 | N9: =(IF(K9<$E$10,$B$10,IF(K9<$E$10+$F$10,$C$10,$D$10))+IF(L9<$E$11,$B$11,IF(L9<$E$11+$F$11,$C$11,$D$11))+IF(M9<$E$12,$B$12,IF(M9<$E$12+$F$12,$C$12,$D$12)))*MIN(2.5,MAX(0.5,(0.09-0.04)/MAX(0.025,(I9-J9)))) -> 3331788.6 | O9: =(N9-Assumptions!$C$22)/Assumptions!$C$25 -> 247.65146
